2022-04-30 01:51:38,216 - CMDB - ERROR -ansible_adhoc: Traceback (most recent call last):
  File "C:/Users/lool/PycharmProjects/get_assets/ansible_adhoc.py", line 56, in process
    res_json = json.loads(res)
  File "C:\Users\lool\AppData\Local\Programs\Python\Python38\lib\json\__init__.py", line 357, in loads
    return _default_decoder.decode(s)
  File "C:\Users\lool\AppData\Local\Programs\Python\Python38\lib\json\decoder.py", line 337, in decode
    obj, end = self.raw_decode(s, idx=_w(s, 0).end())
  File "C:\Users\lool\AppData\Local\Programs\Python\Python38\lib\json\decoder.py", line 355, in raw_decode
    raise JSONDecodeError("Expecting value", s, err.value) from None
json.decoder.JSONDecodeError: Expecting value: line 1 column 1 (char 0)

2022-04-30 12:19:45,765 - CMDB - ERROR -ansible_adhoc: Traceback (most recent call last):
  File "C:/Users/lool/PycharmProjects/get_assets/ansible_adhoc.py", line 75, in process
    result.error[key] = 'offline'
TypeError: 'NoneType' object does not support item assignment

2022-04-30 22:29:56,572 - CMDB - ERROR -ansible_adhoc: Traceback (most recent call last):
  File "C:/Users/lool/PycharmProjects/get_assets/ansible_adhoc.py", line 77, in process
    d1 = {result.data[key]: 2}
KeyError: '192.168.31.143'

2022-04-30 22:30:31,488 - CMDB - ERROR -ansible_adhoc: Traceback (most recent call last):
  File "C:/Users/lool/PycharmProjects/get_assets/ansible_adhoc.py", line 78, in process
    result.data[key].update(d1)
KeyError: '192.168.31.143'

